<?xml version="1.0" ?>
<!-- =================================================================================== -->
<!-- |    This document was autogenerated by xacro from niryo_ned2_gripper1_n_camera.urdf.xacro | -->
<!-- |    EDITING THIS FILE BY HAND IS NOT RECOMMENDED                                 | -->
<!-- =================================================================================== -->
<robot name="niryo_ned2">
  <!-- Enable Gazebo control-->
  <!-- Properties -->
  <!-- Links -->
  <link name="world"/>
  <link name="base_link">
    <inertial>
      <origin rpy="0 0 0" xyz="-0.008924 0.0001357 0.052392"/>
      <mass value="0.71142"/>
      <inertia ixx="0.0017" ixy="0.0" ixz="0.0" iyy="0.0017" iyz="0.0" izz="0.0032"/>
    </inertial>
    <visual>
      <origin rpy="0 0 0" xyz="0 0 0"/>
      <geometry>
        <mesh filename="package://niryo_robot_description/meshes/ned2/collada/base_link.dae"/>
      </geometry>
    </visual>
    <collision>
      <origin rpy="-1.570796326795 0 0" xyz="0 0 0"/>
      <geometry>
        <mesh filename="package://niryo_robot_description/meshes/ned2/stl/base_link.stl"/>
      </geometry>
    </collision>
  </link>
  <link name="shoulder_link">
    <inertial>
      <origin rpy="0 0 0" xyz="-0.031951 0.0080419 0.030675"/>
      <mass value="0.35056"/>
      <inertia ixx="0.00023875" ixy="2.3853E-08" ixz="2.0596E-06" iyy="0.00032638" iyz="-8.9319E-07" izz="0.00030089"/>
    </inertial>
    <visual>
      <origin rpy="0 0 0" xyz="0 0 0"/>
      <geometry>
        <mesh filename="package://niryo_robot_description/meshes/ned2/collada/shoulder_link.dae"/>
      </geometry>
    </visual>
    <collision>
      <origin rpy="0 0 0" xyz="0 0 0"/>
      <geometry>
        <mesh filename="package://niryo_robot_description/meshes/ned2/stl/shoulder_link.stl"/>
      </geometry>
    </collision>
  </link>
  <link name="arm_link">
    <inertial>
      <origin rpy="0 3.14159265359 0" xyz="-0.00096976 0.086432 0.0038832"/>
      <mass value="1.0838"/>
      <inertia ixx="0.008194" ixy="0.00015602" ixz="-3.434E-06" iyy="0.0011945" iyz="-0.00031298" izz="0.007915"/>
    </inertial>
    <visual>
      <origin rpy="0 3.14159265359 0" xyz="0 0 0"/>
      <geometry>
        <mesh filename="package://niryo_robot_description/meshes/ned2/collada/arm_link.dae"/>
      </geometry>
    </visual>
    <collision>
      <origin rpy="0 3.14159265359 0" xyz="0 0 0"/>
      <geometry>
        <mesh filename="package://niryo_robot_description/meshes/ned2/stl/arm_link.stl"/>
      </geometry>
    </collision>
  </link>
  <link name="elbow_link">
    <inertial>
      <origin rpy="0 3.14159265359 0" xyz="-0.019703 0.037336 -1.7431E-09"/>
      <mass value="0.22126"/>
      <inertia ixx="0.00011754" ixy="-1.2314E-05" ixz="-6.2064E-11" iyy="0.00020851" iyz="9.2393E-11" izz="0.00022753"/>
    </inertial>
    <visual>
      <origin rpy="0 3.14159265359 0" xyz="0 0 0"/>
      <geometry>
        <mesh filename="package://niryo_robot_description/meshes/ned2/collada/elbow_link.dae"/>
      </geometry>
    </visual>
    <collision>
      <origin rpy="0 3.14159265359 0" xyz="0 0 0"/>
      <geometry>
        <mesh filename="package://niryo_robot_description/meshes/ned2/stl/elbow_link.stl"/>
      </geometry>
    </collision>
  </link>
  <link name="forearm_link">
    <inertial>
      <origin rpy="0 0 0" xyz="-0.0049532 7.8351E-06 0.08106"/>
      <mass value="0.35686"/>
      <inertia ixx="0.0013664" ixy="-9.6367E-08" ixz="0.00013594" iyy="0.0014781" iyz="-1.4596E-07" izz="0.00023715"/>
    </inertial>
    <visual>
      <origin rpy="0 0 0" xyz="0 0 0"/>
      <geometry>
        <mesh filename="package://niryo_robot_description/meshes/ned2/collada/forearm_link.dae"/>
      </geometry>
    </visual>
    <collision>
      <origin rpy="0 0 0" xyz="0 0 0"/>
      <geometry>
        <mesh filename="package://niryo_robot_description/meshes/ned2/stl/forearm_link.stl"/>
      </geometry>
    </collision>
  </link>
  <link name="wrist_link">
    <inertial>
      <origin rpy="0 0 0" xyz="-0.019666 0.037312 0.0"/>
      <mass value="0.22126"/>
      <inertia ixx="0.0015" ixy="0.0" ixz="0.0" iyy="0.0015" iyz="0.0" izz="0.0015"/>
    </inertial>
    <visual>
      <origin rpy="0 0 0" xyz="0 0 0"/>
      <geometry>
        <mesh filename="package://niryo_robot_description/meshes/ned2/collada/wrist_link.dae"/>
      </geometry>
    </visual>
    <collision>
      <origin rpy="0 0 0" xyz="0 0 0"/>
      <geometry>
        <mesh filename="package://niryo_robot_description/meshes/ned2/stl/wrist_link.stl"/>
      </geometry>
    </collision>
  </link>
  <link name="hand_link">
    <inertial>
      <origin rpy="0 0 0" xyz="0 0 0.009"/>
      <mass value="0.0070027"/>
      <inertia ixx="0.0015" ixy="0.0" ixz="0.0" iyy="0.0015" iyz="0.0" izz="0.0015"/>
    </inertial>
    <visual>
      <origin rpy="0 0 0" xyz="0 0 0"/>
      <geometry>
        <mesh filename="package://niryo_robot_description/meshes/ned2/collada/hand_link.dae"/>
      </geometry>
    </visual>
    <collision>
      <origin rpy="0 0 0" xyz="0 0 0"/>
      <geometry>
        <mesh filename="package://niryo_robot_description/meshes/ned2/stl/hand_link.stl"/>
      </geometry>
    </collision>
  </link>
  <link name="tool_link">
    </link>
  <!-- Joints -->
  <joint name="joint_world" type="fixed">
    <parent link="world"/>
    <child link="base_link"/>
    <origin rpy="0 0 0" xyz="0 0 0"/>
  </joint>
  <joint name="joint_1" type="revolute">
    <origin rpy="0 0 -1.570796326795" xyz="0 0 0.1013"/>
    <parent link="base_link"/>
    <child link="shoulder_link"/>
    <axis xyz="0 0 1"/>
    <limit effort="10.0" lower="-2.999871918328051" upper="2.999871918328051" velocity="10.0"/>
  </joint>
  <joint name="joint_2" type="revolute">
    <origin rpy="1.570796326795 0 1.570796326795" xyz="0 0 0.065"/>
    <parent link="shoulder_link"/>
    <child link="arm_link"/>
    <axis xyz="0 0 1"/>
    <limit effort="10.0" lower="-1.8325957145941667" upper="0.6101671064972578" velocity="8.0"/>
  </joint>
  <joint name="joint_3" type="revolute">
    <origin rpy="0 0 0" xyz="0.012 0.221 0"/>
    <parent link="arm_link"/>
    <child link="elbow_link"/>
    <axis xyz="0 0 1"/>
    <limit effort="7.0" lower="-1.3400637996813345" upper="1.5700981950942021" velocity="8.0"/>
  </joint>
  <joint name="joint_4" type="revolute">
    <origin rpy="0 1.570796326795 0" xyz="0.065 0.0325 0"/>
    <parent link="elbow_link"/>
    <child link="forearm_link"/>
    <axis xyz="0 0 1"/>
    <limit effort="7.0" lower="-2.090031779263347" upper="2.090031779263347" velocity="2.0"/>
  </joint>
  <joint name="joint_5" type="revolute">
    <origin rpy="3.14159265359 -1.570796326795 3.14159265359" xyz="0 0 0.17"/>
    <parent link="forearm_link"/>
    <child link="wrist_link"/>
    <axis xyz="0 0 1"/>
    <limit effort="6.0" lower="-1.9200367101190883" upper="1.9228292369222795" velocity="2.0"/>
  </joint>
  <joint name="joint_6" type="revolute">
    <origin rpy="0 1.570796326795 0" xyz="0.0197 0.00925 0"/>
    <parent link="wrist_link"/>
    <child link="hand_link"/>
    <axis xyz="0 0 1"/>
    <limit effort="5.0" lower="-2.530029283691147" upper="2.530029283691147" velocity="2.0"/>
  </joint>
  <joint name="hand_tool_joint" type="fixed">
    <parent link="hand_link"/>
    <child link="tool_link"/>
    <origin rpy="-1.570796326795 -1.570796326795 0" xyz="0 0 0.0285"/>
  </joint>\
  <!-- Joint from tool_link to base_gripper -->
  <joint name="joint_to_gripper" type="fixed">
    <parent link="tool_link"/>
    <child link="base_gripper_1"/>
    <origin rpy="0 -1.570796326795 1.570796326795" xyz="0.003 0 -0.007"/>
  </joint>
  <!-- Base Gripper -->
  <link name="base_gripper_1">
    <inertial>
      <origin rpy="0 0 0" xyz="0.0028582 0.0022204 0.023772"/>
      <mass value="0.001"/>
      <inertia ixx="1E-06" ixy="0.0" ixz="0.0" iyy="1E-06" iyz="0.0" izz="1E-06"/>
    </inertial>
    <visual>
      <origin rpy="0 0 0" xyz="0 0 0"/>
      <geometry>
        <mesh filename="package://niryo_robot_description/meshes/gripper_1/base_gripper_1.STL"/>
      </geometry>
    </visual>
    <collision>
      <origin rpy="0 0 0" xyz="0 0 0"/>
      <geometry>
        <mesh filename="package://niryo_robot_description/meshes/gripper_1/base_gripper_1.STL"/>
      </geometry>
    </collision>
  </link>
  <!-- Mors 1 -->
  <link name="mors_1">
    <inertial>
      <origin rpy="0 0 0" xyz="-0.0049739 0.0067393 -0.023929"/>
      <mass value="0.0067248"/>
      <inertia ixx="1.1778E-06" ixy="-2.1129E-08" ixz="1.0185E-07" iyy="1.3054E-06" iyz="1.7669E-07" izz="4.3534E-07"/>
    </inertial>
    <visual>
      <origin rpy="0 0 0" xyz="0 0 0"/>
      <geometry>
        <mesh filename="package://niryo_robot_description/meshes/gripper_1/mors_1.STL"/>
      </geometry>
      <material name="">
        <color rgba="0.49804 0.49804 0.49804 1"/>
      </material>
    </visual>
    <collision>
      <origin rpy="0 0 0" xyz="0 0 0"/>
      <geometry>
        <mesh filename="package://niryo_robot_description/meshes/gripper_1/mors_1.STL"/>
      </geometry>
    </collision>
  </link>
  <joint name="joint_base_to_mors_1" type="prismatic">
    <origin rpy="1.5708 0 0" xyz="0.01455 -0.0796 0.0096137"/>
    <parent link="base_gripper_1"/>
    <child link="mors_1"/>
    <axis xyz="0 1 0"/>
    <limit effort="1" lower="-0.01" upper="0.01" velocity="5"/>
  </joint>
  <!-- Mors 2 -->
  <link name="mors_2">
    <inertial>
      <origin rpy="0 0 0" xyz="-0.0049739 -0.0067393 -0.023929"/>
      <mass value="0.0067248"/>
      <inertia ixx="1.1778E-06" ixy="2.1129E-08" ixz="1.0185E-07" iyy="1.3054E-06" iyz="-1.7669E-07" izz="4.3534E-07"/>
    </inertial>
    <visual>
      <origin rpy="0 0 0" xyz="0 0 0"/>
      <geometry>
        <mesh filename="package://niryo_robot_description/meshes/gripper_1/mors_2.STL"/>
      </geometry>
    </visual>
    <collision>
      <origin rpy="0 0 0" xyz="0 0 0"/>
      <geometry>
        <mesh filename="package://niryo_robot_description/meshes/gripper_1/mors_2.STL"/>
      </geometry>
    </collision>
  </link>
  <joint name="joint_base_to_mors_2" type="prismatic">
    <origin rpy="1.5708 0 0" xyz="0.01455 -0.0796 -0.011066"/>
    <parent link="base_gripper_1"/>
    <child link="mors_2"/>
    <axis xyz="0 -1 0"/>
    <limit effort="1" lower="-0.01" upper="0.01" velocity="5"/>
  </joint>
</robot>

